<sdf version='1.9'>
  <world name='world_demo'>
    <physics name='4ms' type='ignored'>
      <max_step_size>0.0040000000000000001</max_step_size>
      <real_time_factor>1</real_time_factor>
      <real_time_update_rate>1000</real_time_update_rate>
    </physics>
    <plugin name='ignition::gazebo::systems::Physics' filename='ignition-gazebo-physics-system'/>
    <plugin name='ignition::gazebo::systems::SceneBroadcaster' filename='ignition-gazebo-scene-broadcaster-system'/>
    <plugin name='ignition::gazebo::systems::UserCommands' filename='ignition-gazebo-user-commands-system'/>
    <plugin name='ignition::gazebo::systems::Sensors' filename='ignition-gazebo-sensors-system'>
      <render_engine>ogre2</render_engine>
    </plugin>
    <spherical_coordinates>
      <surface_model>EARTH_WGS84</surface_model>
      <world_frame_orientation>ENU</world_frame_orientation>
      <latitude_deg>38.775593600000001</latitude_deg>
      <longitude_deg>-9.1375554000000001</longitude_deg>
      <elevation>0</elevation>
      <heading_deg>0</heading_deg>
    </spherical_coordinates>
    <gravity>0 0 -9.8</gravity>
    <magnetic_field>6e-06 2.3e-05 -4.2e-05</magnetic_field>
    <atmosphere type='adiabatic'/>
    <scene>
      <ambient>0.4 0.4 0.4 1</ambient>
      <background>0.7 0.7 0.8 1</background>
      <shadows>true</shadows>
    </scene>
    <plugin name='ignition::gazebo::systems::Imu' filename='libignition-gazebo-imu-system.so'/>
    <plugin name='ignition::gazebo::systems::Contact' filename='libignition-gazebo-contact-system.so'/>
    <include>
      <uri>https://fuel.ignitionrobotics.org/1.0/hexarotor/models/grasspatch</uri>
      <name>grasspatch</name>
      <pose>2.71552 -2.7674 0 0 -0 0.006057</pose>
    </include>
    <include>
      <uri>https://fuel.ignitionrobotics.org/1.0/hexarotor/models/grasspatch</uri>
      <name>grasspatch_0</name>
      <pose>-12.2297 -2.64582 0 0 -0 0</pose>
    </include>
    <include>
      <uri>https://fuel.ignitionrobotics.org/1.0/hexarotor/models/grasspatch</uri>
      <name>grasspatch_1</name>
      <pose>2.62754 12.1062 0 0 -0 0</pose>
    </include>
    <include>
      <uri>https://fuel.ignitionrobotics.org/1.0/hexarotor/models/grasspatch</uri>
      <name>grasspatch_2</name>
      <pose>-12.0931 11.9289 0 0 -0 0</pose>
    </include>
    <include>
      <uri>https://fuel.ignitionrobotics.org/1.0/hexarotor/models/grasspatch</uri>
      <name>grasspatch_3</name>
      <pose>16.9776 12.1962 0 0 -0 0</pose>
    </include>
    <include>
      <uri>https://fuel.ignitionrobotics.org/1.0/hexarotor/models/grasspatch</uri>
      <name>grasspatch_4</name>
      <pose>2.28684 26.938 0 0 -0 0</pose>
    </include>
    <include>
      <uri>https://fuel.ignitionrobotics.org/1.0/hexarotor/models/grasspatch</uri>
      <name>grasspatch_5</name>
      <pose>16.5899 26.9995 0 0 -0 0</pose>
    </include>
    <include>
      <uri>https://fuel.ignitionrobotics.org/1.0/OpenRobotics/models/Oak Tree</uri>
      <name>Pine Tree_11</name>
      <pose>10.0031 4.69601 0 0 -0 0</pose>
    </include>
    <include>
      <uri>https://fuel.ignitionrobotics.org/1.0/OpenRobotics/models/Pine Tree</uri>
      <name>Pine Tree_12</name>
      <pose>9.38057 2.24489 0 0 -0 0</pose>
    </include>
    <include>
      <uri>https://fuel.ignitionrobotics.org/1.0/OpenRobotics/models/Oak Tree</uri>
      <name>Pine Tree_13</name>
      <pose>8.95187 -2.43736 0 0 -0 0</pose>
    </include>
    <include>
      <uri>https://fuel.ignitionrobotics.org/1.0/OpenRobotics/models/Pine Tree</uri>
      <name>Pine Tree_14</name>
      <pose>9.54099 -5.29967 0 0 -0 0</pose>
    </include>
    <include>
      <uri>https://fuel.ignitionrobotics.org/1.0/OpenRobotics/models/Oak Tree</uri>
      <name>Pine Tree_15</name>
      <pose>8.56424 -7.36834 0 0 -0 0</pose>
    </include>
    <include>
      <uri>https://fuel.ignitionrobotics.org/1.0/OpenRobotics/models/Pine Tree</uri>
      <name>Pine Tree_16</name>
      <pose>7.04987 -9.30259 0 0 -0 0</pose>
    </include>
    <include>
      <uri>https://fuel.ignitionrobotics.org/1.0/OpenRobotics/models/Oak Tree</uri>
      <name>Pine Tree_17</name>
      <pose>4.64341 -9.56548 0 0 -0 0</pose>
    </include>
    <include>
      <uri>https://fuel.ignitionrobotics.org/1.0/OpenRobotics/models/Pine Tree</uri>
      <name>Pine Tree_18</name>
      <pose>2.39497 -9.53658 0 0 -0 0</pose>
    </include>
    <include>
      <uri>https://fuel.ignitionrobotics.org/1.0/OpenRobotics/models/Oak Tree</uri>
      <name>Pine Tree_19</name>
      <pose>-0.978211 -9.12685 0 0 -0 0</pose>
    </include>
    <include>
      <uri>https://fuel.ignitionrobotics.org/1.0/OpenRobotics/models/Pine Tree</uri>
      <name>Pine Tree_20</name>
      <pose>-6.60386 -9.4906 0 0 -0 0</pose>
    </include>
    <include>
      <uri>https://fuel.ignitionrobotics.org/1.0/OpenRobotics/models/Oak Tree</uri>
      <name>Pine Tree_21</name>
      <pose>-11.7872 -9.60952 0 0 -0 0</pose>
    </include>
    <include>
      <uri>https://fuel.ignitionrobotics.org/1.0/OpenRobotics/models/Oak Tree</uri>
      <name>Pine Tree_19_1</name>
      <pose>-17.6272 5.0484 0 0 -0 0</pose>
    </include>
    <include>
      <uri>https://fuel.ignitionrobotics.org/1.0/OpenRobotics/models/Oak Tree</uri>
      <name>Pine Tree_19_2</name>
      <pose>-18.7952 -4.79736 0 0 -0 0</pose>
    </include>
    <include>
      <uri>https://fuel.ignitionrobotics.org/1.0/OpenRobotics/models/Oak Tree</uri>
      <name>Pine Tree_19_3</name>
      <pose>-18.6571 13.5589 0 0 -0 0</pose>
    </include>
    <include>
      <uri>https://fuel.ignitionrobotics.org/1.0/OpenRobotics/models/Oak Tree</uri>
      <name>Pine Tree_19_4</name>
      <pose>-13.7446 18.3234 0 0 -0 0</pose>
    </include>
    <include>
      <uri>https://fuel.ignitionrobotics.org/1.0/OpenRobotics/models/Oak Tree</uri>
      <name>Pine Tree_19_5</name>
      <pose>20.1207 7.17708 0 0 -0 0</pose>
    </include>
    <include>
      <uri>https://fuel.ignitionrobotics.org/1.0/OpenRobotics/models/Oak Tree</uri>
      <name>Pine Tree_19_6</name>
      <pose>-3.71164 21.6207 0 0 -0 0</pose>
    </include>
    <include>
      <uri>https://fuel.ignitionrobotics.org/1.0/OpenRobotics/models/Oak Tree</uri>
      <name>Pine Tree_19_7</name>
      <pose>-7.45162 17.9798 0 0 -0 0</pose>
    </include>
    <include>
      <uri>https://fuel.ignitionrobotics.org/1.0/OpenRobotics/models/Oak Tree</uri>
      <name>Pine Tree_19_8</name>
      <pose>-3.88653 25.1364 0 0 -0 0</pose>
    </include>
    <include>
      <uri>https://fuel.ignitionrobotics.org/1.0/OpenRobotics/models/Oak Tree</uri>
      <name>Pine Tree_19_9</name>
      <pose>-4.09489 29.0163 0 0 -0 0</pose>
    </include>
    <include>
      <uri>https://fuel.ignitionrobotics.org/1.0/OpenRobotics/models/Oak Tree</uri>
      <name>Pine Tree_19_10</name>
      <pose>21.3008 12.6766 0 0 -0 0</pose>
    </include>
    <include>
      <uri>https://fuel.ignitionrobotics.org/1.0/OpenRobotics/models/Oak Tree</uri>
      <name>Pine Tree_19_11</name>
      <pose>20.1494 19.5156 0 0 -0 0</pose>
    </include>
    <include>
      <uri>https://fuel.ignitionrobotics.org/1.0/OpenRobotics/models/Oak Tree</uri>
      <name>Pine Tree_19_12</name>
      <pose>13.1837 8.1871 0 0 -0 0</pose>
    </include>
    <include>
      <uri>https://fuel.ignitionrobotics.org/1.0/OpenRobotics/models/Oak Tree</uri>
      <name>Pine Tree_19_13</name>
      <pose>20.0557 23.4209 0 0 -0 0</pose>
    </include>
    <include>
      <uri>https://fuel.ignitionrobotics.org/1.0/OpenRobotics/models/Oak Tree</uri>
      <name>Pine Tree_19_14</name>
      <pose>20.8101 27.2073 0 0 -0 0</pose>
    </include>
    <include>
      <uri>https://fuel.ignitionrobotics.org/1.0/OpenRobotics/models/Oak Tree</uri>
      <name>Pine Tree_19_15</name>
      <pose>18.508 32.5244 0 0 -0 0</pose>
    </include>
    <include>
      <uri>https://fuel.ignitionrobotics.org/1.0/OpenRobotics/models/Oak Tree</uri>
      <name>Pine Tree_19_16</name>
      <pose>12.3362 33.1989 0 0 -0 0</pose>
    </include>
    <include>
      <uri>https://fuel.ignitionrobotics.org/1.0/OpenRobotics/models/Oak Tree</uri>
      <name>Pine Tree_19_17</name>
      <pose>7.92068 33.4253 0 0 -0 0</pose>
    </include>
    <include>
      <uri>https://fuel.ignitionrobotics.org/1.0/OpenRobotics/models/Oak Tree</uri>
      <name>Pine Tree_19_18</name>
      <pose>4.19562 33.3749 0 0 -0 0</pose>
    </include>
    <include>
      <uri>https://fuel.ignitionrobotics.org/1.0/OpenRobotics/models/Oak Tree</uri>
      <name>Pine Tree_19_19</name>
      <pose>-3.1997 32.8927 0 0 -0 0</pose>
    </include>
    <include>
      <uri>https://fuel.gazebosim.org/1.0/omermaayany/models/naked tomato plant</uri>
      <name>naked_tomato</name>
      <pose>0 1.00083 0 0 -0 0</pose>
    </include>
    <model name='vehicle_blue' canonical_link='base_link'>
      <pose>-10 0 0 0 -0 0</pose>
      <frame name='lidar_frame' attached_to='base_link'>
        <pose>0.8 0 0.5 0 0 0</pose>
      </frame>
      <link name='base_link'>
        <pose>0.5 0 0.2 0 -0 0</pose>
        <inertial>
          <mass>1.14395</mass>
          <inertia>
            <ixx>0.095328999999999997</ixx>
            <ixy>0</ixy>
            <ixz>0</ixz>
            <iyy>0.38131700000000002</iyy>
            <iyz>0</iyz>
            <izz>0.47664600000000001</izz>
          </inertia>
          <pose>0 0 0 0 -0 0</pose>
        </inertial>
        <visual name='visual'>
          <geometry>
            <box>
              <size>1.8 0.8 0.3</size>
            </box>
          </geometry>
          <material>
            <ambient>0 0 1 1</ambient>
            <diffuse>0 0 1 1</diffuse>
            <specular>0 0 1 1</specular>
          </material>
        </visual>
        <collision name='collision'>
          <geometry>
            <box>
              <size>1.8 0.8 0.3</size>
            </box>
          </geometry>
          <surface>
            <friction>
              <ode/>
            </friction>
            <bounce/>
            <contact/>
          </surface>
        </collision>
        <sensor name='imu_sensor' type='imu'>
          <pose>0 0 0 0 -0 0</pose>
          <topic>imu</topic>
          <update_rate>1</update_rate>
          <enable_metrics>false</enable_metrics>
          <imu>
            <orientation_reference_frame>
              <localization>CUSTOM</localization>
              <custom_rpy>0 0 0</custom_rpy>
              <grav_dir_x>1 0 0</grav_dir_x>
            </orientation_reference_frame>
            <angular_velocity>
              <x>
                <noise type='none'>
                  <mean>0</mean>
                  <stddev>0</stddev>
                  <bias_mean>0</bias_mean>
                  <bias_stddev>0</bias_stddev>
                  <dynamic_bias_stddev>0</dynamic_bias_stddev>
                  <dynamic_bias_correlation_time>0</dynamic_bias_correlation_time>
                  <precision>0</precision>
                </noise>
              </x>
              <y>
                <noise type='none'>
                  <mean>0</mean>
                  <stddev>0</stddev>
                  <bias_mean>0</bias_mean>
                  <bias_stddev>0</bias_stddev>
                  <dynamic_bias_stddev>0</dynamic_bias_stddev>
                  <dynamic_bias_correlation_time>0</dynamic_bias_correlation_time>
                  <precision>0</precision>
                </noise>
              </y>
              <z>
                <noise type='none'>
                  <mean>0</mean>
                  <stddev>0</stddev>
                  <bias_mean>0</bias_mean>
                  <bias_stddev>0</bias_stddev>
                  <dynamic_bias_stddev>0</dynamic_bias_stddev>
                  <dynamic_bias_correlation_time>0</dynamic_bias_correlation_time>
                  <precision>0</precision>
                </noise>
              </z>
            </angular_velocity>
            <linear_acceleration>
              <x>
                <noise type='none'>
                  <mean>0</mean>
                  <stddev>0</stddev>
                  <bias_mean>0</bias_mean>
                  <bias_stddev>0</bias_stddev>
                  <dynamic_bias_stddev>0</dynamic_bias_stddev>
                  <dynamic_bias_correlation_time>0</dynamic_bias_correlation_time>
                  <precision>0</precision>
                </noise>
              </x>
              <y>
                <noise type='none'>
                  <mean>0</mean>
                  <stddev>0</stddev>
                  <bias_mean>0</bias_mean>
                  <bias_stddev>0</bias_stddev>
                  <dynamic_bias_stddev>0</dynamic_bias_stddev>
                  <dynamic_bias_correlation_time>0</dynamic_bias_correlation_time>
                  <precision>0</precision>
                </noise>
              </y>
              <z>
                <noise type='none'>
                  <mean>0</mean>
                  <stddev>0</stddev>
                  <bias_mean>0</bias_mean>
                  <bias_stddev>0</bias_stddev>
                  <dynamic_bias_stddev>0</dynamic_bias_stddev>
                  <dynamic_bias_correlation_time>0</dynamic_bias_correlation_time>
                  <precision>0</precision>
                </noise>
              </z>
            </linear_acceleration>
            <enable_orientation>true</enable_orientation>
          </imu>
        </sensor>
        <sensor name='gpu_lidar' type='gpu_lidar'>
          <pose>0.8 0 0.5 0 -0 0</pose>
          <topic>lidar</topic>
          <update_rate>10</update_rate>
          <enable_metrics>false</enable_metrics>
          <lidar>
            <scan>
              <horizontal>
                <samples>640</samples>
                <resolution>1</resolution>
                <min_angle>-1.3962600000000001</min_angle>
                <max_angle>1.3962600000000001</max_angle>
              </horizontal>
              <vertical>
                <samples>1</samples>
                <min_angle>0</min_angle>
                <max_angle>0</max_angle>
                <resolution>0.01</resolution>
              </vertical>
            </scan>
            <range>
              <min>0.080000000000000002</min>
              <max>10</max>
              <resolution>0.01</resolution>
            </range>
            <noise>
              <type>none</type>
              <mean>0</mean>
              <stddev>0</stddev>
            </noise>
            <visibility_mask>4294967295</visibility_mask>
          </lidar>
        </sensor>
        <enable_wind>false</enable_wind>
      </link>
      <link name='camera_link'>
        <pose>1.3 0 0.4 0 -0 0</pose>
        <inertial>
          <mass>0.10000000000000001</mass>
          <inertia>
            <ixx>0.00016666700000000001</ixx>
            <iyy>0.00016666700000000001</iyy>
            <izz>0.00016666700000000001</izz>
            <ixy>0</ixy>
            <ixz>0</ixz>
            <iyz>0</iyz>
          </inertia>
          <pose>0 0 0 0 -0 0</pose>
        </inertial>
        <collision name='collision'>
          <geometry>
            <box>
              <size>0.1 0.1 0.1</size>
            </box>
          </geometry>
          <surface>
            <friction>
              <ode/>
            </friction>
            <bounce/>
            <contact/>
          </surface>
        </collision>
        <visual name='visual'>
          <geometry>
            <box>
              <size>0.1 0.1 0.1</size>
            </box>
          </geometry>
        </visual>
        <sensor name='camera' type='camera'>
          <pose>0 0 0 0 -0 0</pose>
          <topic>camera</topic>
          <update_rate>30</update_rate>
          <enable_metrics>false</enable_metrics>
          <camera name='__default__'>
            <pose>0 0 0 0 -0 0</pose>
            <horizontal_fov>1.0469999999999999</horizontal_fov>
            <image>
              <width>380</width>
              <height>240</height>
              <format>RGB_INT8</format>
              <anti_aliasing>4</anti_aliasing>
            </image>
            <camera_info_topic>__default__</camera_info_topic>
            <trigger_topic></trigger_topic>
            <triggered>false</triggered>
            <clip>
              <near>0.10000000000000001</near>
              <far>100</far>
            </clip>
            <save enabled='false'>
              <path>__default__</path>
            </save>
            <visibility_mask>4294967295</visibility_mask>
            <noise>
              <type>none</type>
              <mean>0</mean>
              <stddev>0</stddev>
            </noise>
            <distortion>
              <k1>0</k1>
              <k2>0</k2>
              <k3>0</k3>
              <p1>0</p1>
              <p2>0</p2>
              <center>0.5 0.5</center>
            </distortion>
            <lens>
              <type>stereographic</type>
              <scale_to_hfov>true</scale_to_hfov>
              <cutoff_angle>1.5708</cutoff_angle>
              <env_texture_size>256</env_texture_size>
            </lens>
            <optical_frame_id></optical_frame_id>
          </camera>
        </sensor>
        <enable_wind>false</enable_wind>
      </link>
      <joint name='camera' type='fixed'>
        <parent>base_link</parent>
        <child>camera_link</child>
        <pose>0 0 0 0 -0 0</pose>
      </joint>
      <link name='left_wheel1'>
        <pose>0.1 0.46 0.15 -1.5707 0 0</pose>
        <inertial>
          <mass>1</mass>
          <inertia>
            <ixx>0.043333000000000003</ixx>
            <ixy>0</ixy>
            <ixz>0</ixz>
            <iyy>0.043333000000000003</iyy>
            <iyz>0</iyz>
            <izz>0.080000000000000002</izz>
          </inertia>
          <pose>0 0 0 0 -0 0</pose>
        </inertial>
        <visual name='visual'>
          <geometry>
            <cylinder>
              <radius>0.14999999999999999</radius>
              <length>0.10000000000000001</length>
            </cylinder>
          </geometry>
          <material>
            <ambient>1 0 0 1</ambient>
            <diffuse>1 0 0 1</diffuse>
            <specular>1 0 0 1</specular>
          </material>
        </visual>
        <collision name='collision'>
          <geometry>
            <cylinder>
              <radius>0.14999999999999999</radius>
              <length>0.10000000000000001</length>
            </cylinder>
          </geometry>
          <surface>
            <friction>
              <ode/>
            </friction>
            <bounce/>
            <contact/>
          </surface>
        </collision>
        <enable_wind>false</enable_wind>
      </link>
      <link name='right_wheel1'>
        <pose>0.1 -0.46 0.15 -1.5707 0 0</pose>
        <inertial>
          <mass>1</mass>
          <inertia>
            <ixx>0.043333000000000003</ixx>
            <ixy>0</ixy>
            <ixz>0</ixz>
            <iyy>0.043333000000000003</iyy>
            <iyz>0</iyz>
            <izz>0.080000000000000002</izz>
          </inertia>
          <pose>0 0 0 0 -0 0</pose>
        </inertial>
        <visual name='visual'>
          <geometry>
            <cylinder>
              <radius>0.14999999999999999</radius>
              <length>0.10000000000000001</length>
            </cylinder>
          </geometry>
          <material>
            <ambient>1 0 0 1</ambient>
            <diffuse>1 0 0 1</diffuse>
            <specular>1 0 0 1</specular>
          </material>
        </visual>
        <collision name='collision'>
          <geometry>
            <cylinder>
              <radius>0.14999999999999999</radius>
              <length>0.10000000000000001</length>
            </cylinder>
          </geometry>
          <surface>
            <friction>
              <ode/>
            </friction>
            <bounce/>
            <contact/>
          </surface>
        </collision>
        <enable_wind>false</enable_wind>
      </link>
      <link name='right_wheel2'>
        <pose>0.9 -0.46 0.15 -1.5707 0 0</pose>
        <inertial>
          <mass>1</mass>
          <inertia>
            <ixx>0.043333000000000003</ixx>
            <ixy>0</ixy>
            <ixz>0</ixz>
            <iyy>0.043333000000000003</iyy>
            <iyz>0</iyz>
            <izz>0.080000000000000002</izz>
          </inertia>
          <pose>0 0 0 0 -0 0</pose>
        </inertial>
        <visual name='visual'>
          <geometry>
            <cylinder>
              <radius>0.14999999999999999</radius>
              <length>0.10000000000000001</length>
            </cylinder>
          </geometry>
          <material>
            <ambient>1 0 0 1</ambient>
            <diffuse>1 0 0 1</diffuse>
            <specular>1 0 0 1</specular>
          </material>
        </visual>
        <collision name='collision'>
          <geometry>
            <cylinder>
              <radius>0.14999999999999999</radius>
              <length>0.10000000000000001</length>
            </cylinder>
          </geometry>
          <surface>
            <friction>
              <ode/>
            </friction>
            <bounce/>
            <contact/>
          </surface>
        </collision>
        <enable_wind>false</enable_wind>
      </link>
      <link name='left_wheel2'>
        <pose>0.9 0.46 0.15 -1.5707 0 0</pose>
        <inertial>
          <mass>1</mass>
          <inertia>
            <ixx>0.043333000000000003</ixx>
            <ixy>0</ixy>
            <ixz>0</ixz>
            <iyy>0.043333000000000003</iyy>
            <iyz>0</iyz>
            <izz>0.080000000000000002</izz>
          </inertia>
          <pose>0 0 0 0 -0 0</pose>
        </inertial>
        <visual name='visual'>
          <geometry>
            <cylinder>
              <radius>0.14999999999999999</radius>
              <length>0.10000000000000001</length>
            </cylinder>
          </geometry>
          <material>
            <ambient>1 0 0 1</ambient>
            <diffuse>1 0 0 1</diffuse>
            <specular>1 0 0 1</specular>
          </material>
        </visual>
        <collision name='collision'>
          <geometry>
            <cylinder>
              <radius>0.14999999999999999</radius>
              <length>0.10000000000000001</length>
            </cylinder>
          </geometry>
          <surface>
            <friction>
              <ode/>
            </friction>
            <bounce/>
            <contact/>
          </surface>
        </collision>
        <enable_wind>false</enable_wind>
      </link>
      <joint name='left_wheel1_joint' type='revolute'>
        <pose>0 0 -0 0 -0 0</pose>
        <parent>base_link</parent>
        <child>left_wheel1</child>
        <axis>
          <xyz>0 9.6e-05 1</xyz>
          <limit>
            <lower>-1.7976900000000001e+308</lower>
            <upper>1.7976900000000001e+308</upper>
            <effort>inf</effort>
            <velocity>inf</velocity>
            <stiffness>100000000</stiffness>
            <dissipation>1</dissipation>
          </limit>
          <dynamics>
            <spring_reference>0</spring_reference>
            <spring_stiffness>0</spring_stiffness>
            <damping>0</damping>
            <friction>0</friction>
          </dynamics>
        </axis>
      </joint>
      <joint name='left_wheel2_joint' type='revolute'>
        <pose>0 0 -0 0 -0 0</pose>
        <parent>base_link</parent>
        <child>left_wheel2</child>
        <axis>
          <xyz>0 9.6e-05 1</xyz>
          <limit>
            <lower>-1.7976900000000001e+308</lower>
            <upper>1.7976900000000001e+308</upper>
            <effort>inf</effort>
            <velocity>inf</velocity>
            <stiffness>100000000</stiffness>
            <dissipation>1</dissipation>
          </limit>
          <dynamics>
            <spring_reference>0</spring_reference>
            <spring_stiffness>0</spring_stiffness>
            <damping>0</damping>
            <friction>0</friction>
          </dynamics>
        </axis>
      </joint>
      <joint name='right_wheel1_joint' type='revolute'>
        <pose>0 -0 -0 0 -0 0</pose>
        <parent>base_link</parent>
        <child>right_wheel1</child>
        <axis>
          <xyz>0 9.6e-05 1</xyz>
          <limit>
            <lower>-1.7976900000000001e+308</lower>
            <upper>1.7976900000000001e+308</upper>
            <effort>inf</effort>
            <velocity>inf</velocity>
            <stiffness>100000000</stiffness>
            <dissipation>1</dissipation>
          </limit>
          <dynamics>
            <spring_reference>0</spring_reference>
            <spring_stiffness>0</spring_stiffness>
            <damping>0</damping>
            <friction>0</friction>
          </dynamics>
        </axis>
      </joint>
      <joint name='right_wheel2_joint' type='revolute'>
        <pose>0 -0 -0 0 -0 0</pose>
        <parent>base_link</parent>
        <child>right_wheel2</child>
        <axis>
          <xyz>0 9.6e-05 1</xyz>
          <limit>
            <lower>-1.7976900000000001e+308</lower>
            <upper>1.7976900000000001e+308</upper>
            <effort>inf</effort>
            <velocity>inf</velocity>
            <stiffness>100000000</stiffness>
            <dissipation>1</dissipation>
          </limit>
          <dynamics>
            <spring_reference>0</spring_reference>
            <spring_stiffness>0</spring_stiffness>
            <damping>0</damping>
            <friction>0</friction>
          </dynamics>
        </axis>
      </joint>
      <plugin name='ignition::gazebo::systems::DiffDrive' filename='libignition-gazebo-diff-drive-system.so'>
        <left_joint>left_wheel1_joint</left_joint>
        <left_joint>left_wheel2_joint</left_joint>
        <right_joint>right_wheel1_joint</right_joint>
        <right_joint>right_wheel2_joint</right_joint>
        <wheel_separation>0.92</wheel_separation>
        <wheel_radius>0.15</wheel_radius>
        <odom_publish_frequency>30</odom_publish_frequency>
        <topic>cmd_vel</topic>
        <odom_topic>odom</odom_topic>
        <odom_frame>odom</odom_frame>
        <base_link>base_link</base_link>
        <publish_tf>true</publish_tf>
      </plugin>
      <pose>0 -2.02873 0 0 -0 0</pose>
      <static>false</static>
      <self_collide>false</self_collide>
    </model>
    <include>
      <uri>https://fuel.gazebosim.org/1.0/omermaayany/models/naked tomato plant</uri>
      <name>naked_tomato_1</name>
      <pose>-0.512711 0.992305 0 0 -0 0</pose>
    </include>
    <include>
      <uri>https://fuel.gazebosim.org/1.0/omermaayany/models/naked tomato plant</uri>
      <name>naked_tomato_2</name>
      <pose>0.530276 1.00725 0 0 -0 0</pose>
    </include>
    <include>
      <uri>https://fuel.gazebosim.org/1.0/omermaayany/models/naked tomato plant</uri>
      <name>naked_tomato_3</name>
      <pose>1.03641 1.02134 0 0 -0 0</pose>
    </include>
    <include>
      <uri>https://fuel.gazebosim.org/1.0/omermaayany/models/naked tomato plant</uri>
      <name>naked_tomato_4</name>
      <pose>1.55854 1.00193 0 0 -0 0</pose>
    </include>
    <include>
      <uri>https://fuel.gazebosim.org/1.0/omermaayany/models/naked tomato plant</uri>
      <name>naked_tomato_5</name>
      <pose>1.98602 1.00485 0 0 -0 0</pose>
    </include>
    <include>
      <uri>https://fuel.gazebosim.org/1.0/omermaayany/models/naked tomato plant</uri>
      <name>naked_tomato_6</name>
      <pose>2.52263 1.0129 0 0 -0 0</pose>
    </include>
    <include>
      <uri>https://fuel.gazebosim.org/1.0/omermaayany/models/naked tomato plant</uri>
      <name>naked_tomato_7</name>
      <pose>2.99157 1.01497 0 0 -0 0</pose>
    </include>
    <include>
      <uri>https://fuel.gazebosim.org/1.0/omermaayany/models/naked tomato plant</uri>
      <name>naked_tomato_10</name>
      <pose>-0.972371 1.00517 0 0 -0 0</pose>
    </include>
    <include>
      <uri>https://fuel.gazebosim.org/1.0/omermaayany/models/naked tomato plant</uri>
      <name>naked_tomato_11</name>
      <pose>-0.981306 -1.95292 0 0 -0 0</pose>
    </include>
    <include>
      <uri>https://fuel.gazebosim.org/1.0/omermaayany/models/naked tomato plant</uri>
      <name>naked_tomato_12</name>
      <pose>-0.536654 -1.96891 0 0 -0 0</pose>
    </include>
    <include>
      <uri>https://fuel.gazebosim.org/1.0/omermaayany/models/naked tomato plant</uri>
      <name>naked_tomato_13</name>
      <pose>0.001362 -1.96235 0 0 -0 0</pose>
    </include>
    <include>
      <uri>https://fuel.gazebosim.org/1.0/omermaayany/models/naked tomato plant</uri>
      <name>naked_tomato_14</name>
      <pose>0.513246 -1.95642 0 0 -0 0</pose>
    </include>
    <include>
      <uri>https://fuel.gazebosim.org/1.0/omermaayany/models/naked tomato plant</uri>
      <name>naked_tomato_15</name>
      <pose>1.02642 -1.97694 0 0 -0 0</pose>
    </include>
    <include>
      <uri>https://fuel.gazebosim.org/1.0/omermaayany/models/naked tomato plant</uri>
      <name>naked_tomato_16</name>
      <pose>1.54034 -2.00204 0 0 -0 0</pose>
    </include>
    <include>
      <uri>https://fuel.gazebosim.org/1.0/omermaayany/models/naked tomato plant</uri>
      <name>naked_tomato_17</name>
      <pose>2.01505 -1.97918 0 0 -0 0</pose>
    </include>
    <include>
      <uri>https://fuel.gazebosim.org/1.0/omermaayany/models/naked tomato plant</uri>
      <name>naked_tomato_18</name>
      <pose>2.56074 -1.97493 0 0 -0 0</pose>
    </include>
    <include>
      <uri>https://fuel.gazebosim.org/1.0/omermaayany/models/naked tomato plant</uri>
      <name>naked_tomato_19</name>
      <pose>2.99866 -1.98882 0 0 -0 0</pose>
    </include>
    <include>
      <uri>https://fuel.gazebosim.org/1.0/omermaayany/models/naked tomato plant</uri>
      <name>naked_tomato_24</name>
      <pose>3.04825 -4.95412 0 0 -0 0</pose>
    </include>
    <include>
      <uri>https://fuel.gazebosim.org/1.0/omermaayany/models/naked tomato plant</uri>
      <name>naked_tomato_25</name>
      <pose>2.51558 -4.96851 0 0 -0 0</pose>
    </include>
    <include>
      <uri>https://fuel.gazebosim.org/1.0/omermaayany/models/naked tomato plant</uri>
      <name>naked_tomato_26</name>
      <pose>2.01774 -4.99679 0 0 -0 0</pose>
    </include>
    <include>
      <uri>https://fuel.gazebosim.org/1.0/omermaayany/models/naked tomato plant</uri>
      <name>naked_tomato_27</name>
      <pose>1.52058 -5.00114 0 0 -0 0</pose>
    </include>
    <include>
      <uri>https://fuel.gazebosim.org/1.0/omermaayany/models/naked tomato plant</uri>
      <name>naked_tomato_28</name>
      <pose>1.07016 -4.97508 0 0 -0 0</pose>
    </include>
    <include>
      <uri>https://fuel.gazebosim.org/1.0/omermaayany/models/naked tomato plant</uri>
      <name>naked_tomato_29</name>
      <pose>0.531385 -4.97491 0 0 -0 0</pose>
    </include>
    <include>
      <uri>https://fuel.gazebosim.org/1.0/omermaayany/models/naked tomato plant</uri>
      <name>naked_tomato_30</name>
      <pose>0.026911 -4.97227 0 0 -0 0</pose>
    </include>
    <include>
      <uri>https://fuel.gazebosim.org/1.0/omermaayany/models/naked tomato plant</uri>
      <name>naked_tomato_31</name>
      <pose>-0.477532 -5.01581 0 0 -0 0</pose>
    </include>
    <include>
      <uri>https://fuel.gazebosim.org/1.0/omermaayany/models/naked tomato plant</uri>
      <name>naked_tomato_32</name>
      <pose>-0.983249 -5.04352 0 0 -0 0</pose>
    </include>
    <light name='sun' type='directional'>
      <pose>0 0 10 0 -0 0</pose>
      <cast_shadows>true</cast_shadows>
      <intensity>1</intensity>
      <direction>-0.5 0.1 -0.9</direction>
      <diffuse>0.8 0.8 0.8 1</diffuse>
      <specular>0.2 0.2 0.2 1</specular>
      <attenuation>
        <range>1000</range>
        <linear>0.01</linear>
        <constant>0.90000000000000002</constant>
        <quadratic>0.001</quadratic>
      </attenuation>
      <spot>
        <inner_angle>0</inner_angle>
        <outer_angle>0</outer_angle>
        <falloff>0</falloff>
      </spot>
    </light>
  </world>
</sdf>
