<sdf version='1.9'>
  <world name='world_demo'>
    <physics name='4ms' type='ignored'>
      <max_step_size>0.0040000000000000001</max_step_size>
      <real_time_factor>1</real_time_factor>
      <real_time_update_rate>1000</real_time_update_rate>
    </physics>
    <plugin name='ignition::gazebo::systems::Physics' filename='ignition-gazebo-physics-system'/>
    <plugin name='ignition::gazebo::systems::SceneBroadcaster' filename='ignition-gazebo-scene-broadcaster-system'/>
    <plugin name='ignition::gazebo::systems::UserCommands' filename='ignition-gazebo-user-commands-system'/>
    <plugin name='ignition::gazebo::systems::Sensors' filename='ignition-gazebo-sensors-system'>
      <render_engine>ogre2</render_engine>
    </plugin>
    <spherical_coordinates>
      <surface_model>EARTH_WGS84</surface_model>
      <world_frame_orientation>ENU</world_frame_orientation>
      <latitude_deg>38.775593600000001</latitude_deg>
      <longitude_deg>-9.1375554000000001</longitude_deg>
      <elevation>0</elevation>
      <heading_deg>0</heading_deg>
    </spherical_coordinates>
    <gravity>0 0 -9.8</gravity>
    <magnetic_field>6e-06 2.3e-05 -4.2e-05</magnetic_field>
    <atmosphere type='adiabatic'/>
    <scene>
      <ambient>0.4 0.4 0.4 1</ambient>
      <background>0.7 0.7 0.8 1</background>
      <shadows>true</shadows>
    </scene>
    
    
    
    <include>
      <uri>https://fuel.ignitionrobotics.org/1.0/hexarotor/models/grasspatch</uri>
      <name>grasspatch</name>
      <pose>2.71574 -2.80395 0 0 -0 0.006057</pose>
    </include>
    <include>
      <uri>https://fuel.ignitionrobotics.org/1.0/hexarotor/models/grasspatch</uri>
      <name>grasspatch_0</name>
      <pose>-12.2297 -2.64582 0 0 -0 0</pose>
    </include>
    <include>
      <uri>https://fuel.ignitionrobotics.org/1.0/hexarotor/models/grasspatch</uri>
      <name>grasspatch_1</name>
      <pose>2.62754 12.1062 0 0 -0 0</pose>
    </include>
    <include>
      <uri>https://fuel.ignitionrobotics.org/1.0/hexarotor/models/grasspatch</uri>
      <name>grasspatch_2</name>
      <pose>-12.0931 11.9289 0 0 -0 0</pose>
    </include>
    <include>
      <uri>https://fuel.ignitionrobotics.org/1.0/hexarotor/models/grasspatch</uri>
      <name>grasspatch_3</name>
      <pose>16.9776 12.1962 0 0 -0 0</pose>
    </include>
    <include>
      <uri>https://fuel.ignitionrobotics.org/1.0/hexarotor/models/grasspatch</uri>
      <name>grasspatch_4</name>
      <pose>2.28684 26.938 0 0 -0 0</pose>
    </include>
    <include>
      <uri>https://fuel.ignitionrobotics.org/1.0/hexarotor/models/grasspatch</uri>
      <name>grasspatch_5</name>
      <pose>16.5899 26.9995 0 0 -0 0</pose>
    </include>
    <include>
      <uri>https://fuel.ignitionrobotics.org/1.0/OpenRobotics/models/Oak Tree</uri>
      <name>Pine Tree_11</name>
      <pose>10.0031 4.69601 0 0 -0 0</pose>
    </include>
    <include>
      <uri>https://fuel.ignitionrobotics.org/1.0/OpenRobotics/models/Pine Tree</uri>
      <name>Pine Tree_12</name>
      <pose>9.38057 2.24489 0 0 -0 0</pose>
    </include>
    <include>
      <uri>https://fuel.ignitionrobotics.org/1.0/OpenRobotics/models/Oak Tree</uri>
      <name>Pine Tree_13</name>
      <pose>8.95187 -2.43736 0 0 -0 0</pose>
    </include>
    <include>
      <uri>https://fuel.ignitionrobotics.org/1.0/OpenRobotics/models/Pine Tree</uri>
      <name>Pine Tree_14</name>
      <pose>9.54099 -5.29967 0 0 -0 0</pose>
    </include>
    <include>
      <uri>https://fuel.ignitionrobotics.org/1.0/OpenRobotics/models/Oak Tree</uri>
      <name>Pine Tree_15</name>
      <pose>8.56424 -7.36834 0 0 -0 0</pose>
    </include>
    <include>
      <uri>https://fuel.ignitionrobotics.org/1.0/OpenRobotics/models/Pine Tree</uri>
      <name>Pine Tree_16</name>
      <pose>7.04987 -9.30259 0 0 -0 0</pose>
    </include>
    <include>
      <uri>https://fuel.ignitionrobotics.org/1.0/OpenRobotics/models/Oak Tree</uri>
      <name>Pine Tree_17</name>
      <pose>4.64341 -9.56548 0 0 -0 0</pose>
    </include>
    <include>
      <uri>https://fuel.ignitionrobotics.org/1.0/OpenRobotics/models/Pine Tree</uri>
      <name>Pine Tree_18</name>
      <pose>2.39497 -9.53658 0 0 -0 0</pose>
    </include>
    <include>
      <uri>https://fuel.ignitionrobotics.org/1.0/OpenRobotics/models/Oak Tree</uri>
      <name>Pine Tree_19</name>
      <pose>-0.978211 -9.12685 0 0 -0 0</pose>
    </include>
    <include>
      <uri>https://fuel.ignitionrobotics.org/1.0/OpenRobotics/models/Pine Tree</uri>
      <name>Pine Tree_20</name>
      <pose>-6.60386 -9.4906 0 0 -0 0</pose>
    </include>
    <include>
      <uri>https://fuel.ignitionrobotics.org/1.0/OpenRobotics/models/Oak Tree</uri>
      <name>Pine Tree_21</name>
      <pose>-11.7872 -9.60952 0 0 -0 0</pose>
    </include>


    <include>
      <uri>https://fuel.ignitionrobotics.org/1.0/OpenRobotics/models/Oak Tree</uri>
      <name>Pine Tree_19_1</name>
      <pose>-17.6272 5.0484 0 0 -0 0</pose>
    </include>
    <include>
      <uri>https://fuel.ignitionrobotics.org/1.0/OpenRobotics/models/Oak Tree</uri>
      <name>Pine Tree_19_2</name>
      <pose>-18.7952 -4.79736 0 0 -0 0</pose>
    </include>
    <include>
      <uri>https://fuel.ignitionrobotics.org/1.0/OpenRobotics/models/Oak Tree</uri>
      <name>Pine Tree_19_3</name>
      <pose>-18.6571 13.5589 0 0 -0 0</pose>
    </include>
    <include>
      <uri>https://fuel.ignitionrobotics.org/1.0/OpenRobotics/models/Oak Tree</uri>
      <name>Pine Tree_19_4</name>
      <pose>-13.7446 18.3234 0 0 -0 0</pose>
    </include>
    <include>
      <uri>https://fuel.ignitionrobotics.org/1.0/OpenRobotics/models/Oak Tree</uri>
      <name>Pine Tree_19_5</name>
      <pose>20.1207 7.17708 0 0 -0 0</pose>
    </include>
    <include>
      <uri>https://fuel.ignitionrobotics.org/1.0/OpenRobotics/models/Oak Tree</uri>
      <name>Pine Tree_19_6</name>
      <pose>-3.71164 21.6207 0 0 -0 0</pose>
    </include>
    <include>
      <uri>https://fuel.ignitionrobotics.org/1.0/OpenRobotics/models/Oak Tree</uri>
      <name>Pine Tree_19_7</name>
      <pose>-7.45162 17.9798 0 0 -0 0</pose>
    </include>
    <include>
      <uri>https://fuel.ignitionrobotics.org/1.0/OpenRobotics/models/Oak Tree</uri>
      <name>Pine Tree_19_8</name>
      <pose>-3.88653 25.1364 0 0 -0 0</pose>
    </include>
    <include>
      <uri>https://fuel.ignitionrobotics.org/1.0/OpenRobotics/models/Oak Tree</uri>
      <name>Pine Tree_19_9</name>
      <pose>-4.09489 29.0163 0 0 -0 0</pose>
    </include>
    <include>
      <uri>https://fuel.ignitionrobotics.org/1.0/OpenRobotics/models/Oak Tree</uri>
      <name>Pine Tree_19_10</name>
      <pose>21.3008 12.6766 0 0 -0 0</pose>
    </include>
    <include>
      <uri>https://fuel.ignitionrobotics.org/1.0/OpenRobotics/models/Oak Tree</uri>
      <name>Pine Tree_19_11</name>
      <pose>20.1494 19.5156 0 0 -0 0</pose>
    </include>
    <include>
      <uri>https://fuel.ignitionrobotics.org/1.0/OpenRobotics/models/Oak Tree</uri>
      <name>Pine Tree_19_12</name>
      <pose>13.1837 8.1871 0 0 -0 0</pose>
    </include>
    <include>
      <uri>https://fuel.ignitionrobotics.org/1.0/OpenRobotics/models/Oak Tree</uri>
      <name>Pine Tree_19_13</name>
      <pose>20.0557 23.4209 0 0 -0 0</pose>
    </include>
    <include>
      <uri>https://fuel.ignitionrobotics.org/1.0/OpenRobotics/models/Oak Tree</uri>
      <name>Pine Tree_19_14</name>
      <pose>20.8101 27.2073 0 0 -0 0</pose>
    </include>
    <include>
      <uri>https://fuel.ignitionrobotics.org/1.0/OpenRobotics/models/Oak Tree</uri>
      <name>Pine Tree_19_15</name>
      <pose>18.508 32.5244 0 0 -0 0</pose>
    </include>
    <include>
      <uri>https://fuel.ignitionrobotics.org/1.0/OpenRobotics/models/Oak Tree</uri>
      <name>Pine Tree_19_16</name>
      <pose>12.3362 33.1989 0 0 -0 0</pose>
    </include>
    <include>
      <uri>https://fuel.ignitionrobotics.org/1.0/OpenRobotics/models/Oak Tree</uri>
      <name>Pine Tree_19_17</name>
      <pose>7.92068 33.4253 0 0 -0 0</pose>
    </include>
    <include>
      <uri>https://fuel.ignitionrobotics.org/1.0/OpenRobotics/models/Oak Tree</uri>
      <name>Pine Tree_19_18</name>
      <pose>4.19562 33.3749 0 0 -0 0</pose>
    </include>
    <include>
      <uri>https://fuel.ignitionrobotics.org/1.0/OpenRobotics/models/Oak Tree</uri>
      <name>Pine Tree_19_19</name>
      <pose>-3.1997 32.8927 0 0 -0 0</pose>
    </include>
    <light name='sun' type='directional'>
      <pose>0 0 10 0 -0 0</pose>
      <cast_shadows>true</cast_shadows>
      <intensity>1</intensity>
      <direction>-0.5 0.1 -0.9</direction>
      <diffuse>0.8 0.8 0.8 1</diffuse>
      <specular>0.2 0.2 0.2 1</specular>
      <attenuation>
        <range>1000</range>
        <linear>0.01</linear>
        <constant>0.90000000000000002</constant>
        <quadratic>0.001</quadratic>
      </attenuation>
      <spot>
        <inner_angle>0</inner_angle>
        <outer_angle>0</outer_angle>
        <falloff>0</falloff>
      </spot>
    </light>
    	
    	
    <include>
        <uri>
	https://fuel.gazebosim.org/1.0/omermaayany/models/naked tomato plant
	</uri>
    </include>

    <plugin filename="libignition-gazebo-imu-system.so"
                name="ignition::gazebo::systems::Imu">
        </plugin>

        <plugin filename="libignition-gazebo-contact-system.so"
            name="ignition::gazebo::systems::Contact">
        </plugin>
        
        
        <model name='vehicle_blue' canonical_link='base_link'>
            <frame name="lidar_frame" attached_to='base_link'>
                <pose>0.8 0 0.5 0 0 0</pose>
            </frame>

            <link name='base_link'>
                <pose relative_to='__model__'>0.5 0 0.2 0 0 0</pose>
                    <inertial> <!--inertial properties of the link mass, inertia matix-->
                        <mass>1.14395</mass>
                        <inertia>
                            <ixx>0.095329</ixx>
                            <ixy>0</ixy>
                            <ixz>0</ixz>
                            <iyy>0.381317</iyy>
                            <iyz>0</iyz>
                            <izz>0.476646</izz>
                        </inertia>
                    </inertial>
                    <visual name='visual'>
                        <geometry>
                            <box>
                                <size>1.8 0.8 0.3</size>
                            </box>
                        </geometry>
                        <!--let's add color to our link-->
                        <material>
                            <ambient>0.0 0.0 1.0 1</ambient>
                            <diffuse>0.0 0.0 1.0 1</diffuse>
                            <specular>0.0 0.0 1.0 1</specular>
                        </material>
                    </visual>
                    <collision name='collision'>
                        <geometry>
                            <box>
                                <size>1.8 0.8 0.3</size>
                            </box>
                        </geometry>
                    </collision>
                    <sensor name="imu_sensor" type="imu">
                        <always_on>1</always_on>
                        <update_rate>1</update_rate>
                        <visualize>true</visualize>
                        <topic>imu</topic>
                    </sensor>

                    <sensor name='gpu_lidar' type='gpu_lidar'>"
                        <pose relative_to='lidar_frame'>0 0 0 0 0 0</pose>
                        <topic>lidar</topic>
                        <update_rate>10</update_rate>
                        <ray>
                            <scan>
                                <horizontal>
                                    <samples>640</samples>
                                    <resolution>1</resolution>
                                    <min_angle>-1.396263</min_angle>
                                    <max_angle>1.396263</max_angle>
                                </horizontal>
                                <vertical>
                                    <samples>1</samples>
                                    <resolution>0.01</resolution>
                                    <min_angle>0</min_angle>
                                    <max_angle>0</max_angle>
                                </vertical>
                            </scan>
                            <range>
                                <min>0.08</min>
                                <max>10.0</max>
                                <resolution>0.01</resolution>
                            </range>
                        </ray>
                        <always_on>1</always_on>
                        <visualize>true</visualize>
                    </sensor>
                </link>

                <link name="camera_link">
                    <pose relative_to='base_link'>0.8 0.0 0.2 0 0 0</pose>
                    <inertial>
                        <mass>0.1</mass>
                        <inertia>
                            <ixx>0.000166667</ixx>
                            <iyy>0.000166667</iyy>
                            <izz>0.000166667</izz>
                        </inertia>
                    </inertial>

                    <collision name="collision">
                        <geometry>
                            <box>
                                <size>0.1 0.1 0.1</size>
                            </box>
                        </geometry>
                    </collision>
                    <visual name="visual">
                        <geometry>
                            <box>
                                <size>0.1 0.1 0.1</size>
                            </box>
                        </geometry>
                    </visual>

                    <sensor name="camera" type="camera">
                        <camera>
                            <horizontal_fov>1.047</horizontal_fov>
                            <image>
                                <width>380</width>
                                <height>240</height>
                            </image>
                            <clip>
                                <near>0.1</near>
                                <far>100</far>
                            </clip>
                        </camera>
                        <always_on>1</always_on>
                        <update_rate>30</update_rate>
                        <visualize>true</visualize>
                        <topic>camera</topic>
                    </sensor>
                </link>

                <joint name='camera' type='fixed'>
                    <parent>base_link</parent>
                    <child>camera_link</child>
                </joint>

                <link name='left_wheel1'>
                    <pose relative_to="base_link">-0.4 0.46 -0.05 -1.5707 0 0</pose>
                    <inertial>
                        <mass>1</mass>
                        <inertia>
                            <ixx>0.043333</ixx>
                            <ixy>0</ixy>
                            <ixz>0</ixz>
                            <iyy>0.043333</iyy>
                            <iyz>0</iyz>
                            <izz>0.08</izz>
                        </inertia>
                    </inertial>
                    <visual name='visual'>
                        <geometry>
                            <cylinder>
                                <radius>0.15</radius>
                                <length>0.10</length>
                            </cylinder>
                        </geometry>
                        <material>
                            <ambient>1.0 0.0 0.0 1</ambient>
                            <diffuse>1.0 0.0 0.0 1</diffuse>
                            <specular>1.0 0.0 0.0 1</specular>
                        </material>
                    </visual>
                    <collision name='collision'>
                        <geometry>
                            <cylinder>
                                <radius>0.15</radius>
                                <length>0.10</length>
                            </cylinder>
                        </geometry>
                    </collision>
                </link>

                <!--The same as left wheel but with different position-->
                <link name='right_wheel1'>
                    <pose relative_to="base_link">-0.4 -0.46 -0.05 -1.5707 0 0</pose> <!--angles are in radian-->
                    <inertial>
                        <mass>1</mass>
                        <inertia>
                            <ixx>0.043333</ixx>
                            <ixy>0</ixy>
                            <ixz>0</ixz>
                            <iyy>0.043333</iyy>
                            <iyz>0</iyz>
                            <izz>0.08</izz>
                        </inertia>
                    </inertial>
                    <visual name='visual'>
                        <geometry>
                            <cylinder>
                                <radius>0.15</radius>
                                <length>0.10</length>
                            </cylinder>
                        </geometry>
                        <material>
                            <ambient>1.0 0.0 0.0 1</ambient>
                            <diffuse>1.0 0.0 0.0 1</diffuse>
                            <specular>1.0 0.0 0.0 1</specular>
                        </material>
                    </visual>
                    <collision name='collision'>
                        <geometry>
                            <cylinder>
                                <radius>0.15</radius>
                                <length>0.10</length>
                            </cylinder>
                        </geometry>
                    </collision>
                </link>

                <link name='right_wheel2'>
                    <pose relative_to="base_link">0.4 -0.46 -0.05 -1.5707 0 0</pose> <!--angles are in radian-->
                    <inertial>
                        <mass>1</mass>
                        <inertia>
                            <ixx>0.043333</ixx>
                            <ixy>0</ixy>
                            <ixz>0</ixz>
                            <iyy>0.043333</iyy>
                            <iyz>0</iyz>
                            <izz>0.08</izz>
                        </inertia>
                    </inertial>
                    <visual name='visual'>
                        <geometry>
                            <cylinder>
                                <radius>0.15</radius>
                                <length>0.10</length>
                            </cylinder>
                        </geometry>
                        <material>
                            <ambient>1.0 0.0 0.0 1</ambient>
                            <diffuse>1.0 0.0 0.0 1</diffuse>
                            <specular>1.0 0.0 0.0 1</specular>
                        </material>
                    </visual>
                    <collision name='collision'>
                        <geometry>
                            <cylinder>
                                <radius>0.15</radius>
                                <length>0.10</length>
                            </cylinder>
                        </geometry>
                    </collision>
                </link>

                <link name='left_wheel2'>
                    <pose relative_to="base_link">0.4 0.46 -0.05 -1.5707 0 0</pose> <!--angles are in radian-->
                    <inertial>
                        <mass>1</mass>
                        <inertia>
                            <ixx>0.043333</ixx>
                            <ixy>0</ixy>
                            <ixz>0</ixz>
                            <iyy>0.043333</iyy>
                            <iyz>0</iyz>
                            <izz>0.08</izz>
                        </inertia>
                    </inertial>
                    <visual name='visual'>
                        <geometry>
                            <cylinder>
                                <radius>0.15</radius>
                                <length>0.10</length>
                            </cylinder>
                        </geometry>
                        <material>
                            <ambient>1.0 0.0 0.0 1</ambient>
                            <diffuse>1.0 0.0 0.0 1</diffuse>
                            <specular>1.0 0.0 0.0 1</specular>
                        </material>
                    </visual>
                    <collision name='collision'>
                        <geometry>
                            <cylinder>
                                <radius>0.15</radius>
                                <length>0.10</length>
                            </cylinder>
                        </geometry>
                    </collision>
                </link>

                <joint name='left_wheel1_joint' type='revolute'>
                    <pose relative_to='left_wheel1'/>
                    <parent>base_link</parent>
                    <child>left_wheel1</child>
                    <axis>
                        <xyz expressed_in='__model__'>0 1 0</xyz> <!--can be defined as any frame or even arbitrary frames-->
                        <limit>
                            <lower>-1.79769e+308</lower>    <!--negative infinity-->
                            <upper>1.79769e+308</upper>     <!--positive infinity-->
                        </limit>
                    </axis>
                </joint>

                <joint name='left_wheel2_joint' type='revolute'>
                    <pose relative_to='left_wheel2'/>
                    <parent>base_link</parent>
                    <child>left_wheel2</child>
                    <axis>
                        <xyz expressed_in='__model__'>0 1 0</xyz> <!--can be defined as any frame or even arbitrary frames-->
                        <limit>
                            <lower>-1.79769e+308</lower>    <!--negative infinity-->
                            <upper>1.79769e+308</upper>     <!--positive infinity-->
                        </limit>
                    </axis>
                </joint>

                <joint name='right_wheel1_joint' type='revolute'>
                    <pose relative_to='right_wheel1'/>
                    <parent>base_link</parent>
                    <child>right_wheel1</child>
                    <axis>
                        <xyz expressed_in='__model__'>0 1 0</xyz>
                        <limit>
                            <lower>-1.79769e+308</lower>    <!--negative infinity-->
                            <upper>1.79769e+308</upper>     <!--positive infinity-->
                        </limit>
                    </axis>
                </joint>

                <joint name='right_wheel2_joint' type='revolute'>
                    <pose relative_to='right_wheel2'/>
                    <parent>base_link</parent>
                    <child>right_wheel2</child>
                    <axis>
                        <xyz expressed_in='__model__'>0 1 0</xyz>
                        <limit>
                            <lower>-1.79769e+308</lower>    <!--negative infinity-->
                            <upper>1.79769e+308</upper>     <!--positive infinity-->
                        </limit>
                    </axis>
                </joint>

                <plugin
    		    filename="libignition-gazebo-diff-drive-system.so"
    		    name="ignition::gazebo::systems::DiffDrive">
    		    <left_joint>left_wheel1_joint</left_joint>
		    <left_joint>left_wheel2_joint</left_joint>
		    <right_joint>right_wheel1_joint</right_joint>
		    <right_joint>right_wheel2_joint</right_joint>
		    <wheel_separation>0.92</wheel_separation>
		    <wheel_radius>0.15</wheel_radius>
		    <odom_publish_frequency>30</odom_publish_frequency>
		    <topic>cmd_vel</topic>
		    <odom_topic>odom</odom_topic>
		    <odom_frame>odom</odom_frame>
		    <base_link>base_link</base_link>
		    <publish_tf>true</publish_tf>
		</plugin>

            </model>
            
  </world>
</sdf>
