<?xml version="1.0"?>
<sdf version="1.9">
    <!-- ==================== ROBÔ ==================== -->
    <model name="vehicle_blue" canonical_link="base_link">

      <!-- Frames auxiliares -->
      <frame name="caster_frame" attached_to="base_link">
        <pose>0.8 0 -0.2 0 0 0</pose>
      </frame>
      <frame name="lidar_frame" attached_to="base_link">
        <pose>0.8 0 0.5 0 0 0</pose>
      </frame>

      <!-- Chassi -->
      <link name="base_link">
        <pose relative_to="__model__">0.5 0 0.4 0 0 0</pose>
        <inertial>
          <mass>1.14395</mass>
          <inertia>
            <ixx>0.095329</ixx><ixy>0</ixy><ixz>0</ixz>
            <iyy>0.381317</iyy><iyz>0</iyz><izz>0.476646</izz>
          </inertia>
        </inertial>

        <visual name="visual">
          <geometry><box><size>2.0 1.0 0.5</size></box></geometry>
          <material>
            <ambient>0.0 1.0 0.0 1</ambient>
            <diffuse>0.5 0.0 1.0 1</diffuse>
            <specular>1.0 0.0 0.5 1</specular>
          </material>
        </visual>

        <collision name="collision">
          <geometry><box><size>2.0 1.0 0.5</size></box></geometry>
        </collision>

        <!-- IMU no chassi -->
        <sensor name="imu_sensor" type="imu">
          <always_on>1</always_on>
          <update_rate>1</update_rate>
          <visualize>true</visualize>
          <topic>imu</topic>
        </sensor>
      </link>

      <!-- LiDAR em link próprio -->
      <link name="lidar_link">
        <pose>0.8 0.0 0.8 0 0 0</pose>
        <inertial>
          <mass>0.1</mass>
          <inertia>
            <ixx>0.000166667</ixx><iyy>0.000166667</iyy><izz>0.000166667</izz>
          </inertia>
        </inertial>
        <collision name="collision">
          <geometry><cylinder><radius>0.24</radius><length>0.24</length></cylinder></geometry>
        </collision>
        <visual name="visual">
          <geometry><cylinder><radius>0.24</radius><length>0.24</length></cylinder></geometry>
          <material><diffuse>0.1 0.1 0.1 1</diffuse></material>
        </visual>

        <sensor name="gpu_lidar" type="gpu_lidar">
          <pose relative_to="lidar_frame">0 0 0 0 0 0</pose>
          <topic>/scan</topic>
          <update_rate>10</update_rate>
          <lidar>
            <scan>
              <horizontal>
                <samples>250</samples>
                <resolution>1</resolution>
                <min_angle>-2.0</min_angle>
                <max_angle> 2.0</max_angle>
              </horizontal>
              <vertical>
                <samples>1</samples>
                <resolution>0.01</resolution>
                <min_angle>0</min_angle>
                <max_angle>0</max_angle>
              </vertical>
            </scan>
            <range>
              <min>0.08</min>
              <max>10.0</max>
              <resolution>0.01</resolution>
            </range>
          </lidar>
          <always_on>1</always_on>
          <visualize>true</visualize>
        </sensor>
      </link>

      <!-- Junta fixa LiDAR -->
      <joint name="lidar_fixed" type="fixed">
        <parent>base_link</parent>
        <child>lidar_link</child>
      </joint>

      <!-- Câmera em link próprio + sensor -->
      <link name="camera">
        <pose relative_to="base_link">1 0 0 0 0 0</pose>
        <visual name="visual">
          <geometry><box><size>0.1 0.1 0.1</size></box></geometry>
          <material>
            <ambient>1.0 0.0 0.0 1</ambient>
            <diffuse>1.0 0.0 0.0 1</diffuse>
            <specular>1.0 0.0 0.0 1</specular>
          </material>
        </visual>
        <collision name="collision">
          <geometry><box><size>0.1 0.1 0.1</size></box></geometry>
        </collision>

        <sensor type="camera" name="camera_sensor">
          <topic>/camera/image_raw</topic>
          <update_rate>30.0</update_rate>
          <camera name="head">
            <horizontal_fov>1.3962634</horizontal_fov>
            <image><width>800</width><height>800</height><format>R8G8B8</format></image>
            <clip><near>0.02</near><far>300</far></clip>
            <noise><type>gaussian</type><mean>0.0</mean><stddev>0.007</stddev></noise>
          </camera>
        </sensor>
      </link>

      <joint name="camera_joint" type="fixed">
        <parent>base_link</parent>
        <child>camera</child>
        <pose>1 0 0 0 0 0</pose>
      </joint>

      <!-- Rodas -->
      <link name="roda_esquerda">
        <pose relative_to="base_link">-0.7 0.6 0 -1.5707 0 0</pose>
        <inertial>
          <mass>1</mass>
          <inertia>
            <ixx>0.043333</ixx><ixy>0</ixy><ixz>0</ixz>
            <iyy>0.043333</iyy><iyz>0</iyz><izz>0.08</izz>
          </inertia>
        </inertial>
        <visual name="visual">
          <geometry><cylinder><radius>0.4</radius><length>0.2</length></cylinder></geometry>
          <material><ambient>1 0 0 1</ambient><diffuse>1 0 0 1</diffuse><specular>1 0 0 1</specular></material>
        </visual>
        <collision name="collision">
          <geometry><cylinder><radius>0.4</radius><length>0.2</length></cylinder></geometry>
        </collision>
      </link>

      <link name="roda_direita">
        <pose relative_to="base_link">-0.7 -0.6 0 -1.5707 0 0</pose>
        <inertial>
          <mass>1</mass>
          <inertia>
            <ixx>0.043333</ixx><ixy>0</ixy><ixz>0</ixz>
            <iyy>0.043333</iyy><iyz>0</iyz><izz>0.08</izz>
          </inertia>
        </inertial>
        <visual name="visual">
          <geometry><cylinder><radius>0.4</radius><length>0.2</length></cylinder></geometry>
          <material><ambient>1 0 0 1</ambient><diffuse>1 0 0 1</diffuse><specular>1 0 0 1</specular></material>
        </visual>
        <collision name="collision">
          <geometry><cylinder><radius>0.4</radius><length>0.2</length></cylinder></geometry>
        </collision>
      </link>

      <link name="caster">
        <pose relative_to="caster_frame"/>
        <inertial>
          <mass>1</mass>
          <inertia>
            <ixx>0.016</ixx><ixy>0</ixy><ixz>0</ixz>
            <iyy>0.016</iyy><iyz>0</iyz><izz>0.016</izz>
          </inertia>
        </inertial>
        <visual name="visual">
          <geometry><sphere><radius>0.2</radius></sphere></geometry>
          <material><ambient>0 1 0 1</ambient><diffuse>0 1 0 1</diffuse><specular>0 1 0 1</specular></material>
        </visual>
        <collision name="collision">
          <geometry><sphere><radius>0.2</radius></sphere></geometry>
        </collision>
      </link>

      <!-- Juntas -->
      <joint name="junta_roda_esquerda" type="revolute">
        <pose relative_to="roda_esquerda"/>
        <parent>base_link</parent>
        <child>roda_esquerda</child>
        <axis>
          <xyz expressed_in="__model__">0 1 0</xyz>
          <limit><lower>-1.79769e+308</lower><upper>1.79769e+308</upper></limit>
        </axis>
      </joint>

      <joint name="junta_roda_direita" type="revolute">
        <pose relative_to="roda_direita"/>
        <parent>base_link</parent>
        <child>roda_direita</child>
        <axis>
          <xyz expressed_in="__model__">0 1 0</xyz>
          <limit><lower>-1.79769e+308</lower><upper>1.79769e+308</upper></limit>
        </axis>
      </joint>

      <joint name="caster_wheel" type="ball">
        <parent>base_link</parent>
        <child>caster</child>
      </joint>

      <!-- Plugins do modelo -->
      <plugin filename="libignition-gazebo-diff-drive-system.so" name="ignition::gazebo::systems::DiffDrive">
        <left_joint>junta_roda_esquerda</left_joint>
        <right_joint>junta_roda_direita</right_joint>
        <wheel_separation>1.2</wheel_separation>
        <wheel_radius>0.4</wheel_radius>
        <odom_publish_frequency>1</odom_publish_frequency>
        <topic>/cmd_vel</topic>
        <odom_topic>/odom</odom_topic>
      </plugin>

      <plugin filename="libignition-gazebo-triggered-publisher-system.so" name="ignition::gazebo::systems::TriggeredPublisher">
        <input type="ignition.msgs.Boolean" topic="/wall/touched">
          <match>data: true</match>
        </input>
        <output type="ignition.msgs.Twist" topic="/cmd_vel">
          linear: {x: 0.0}, angular: {z: 0.0}
        </output>
      </plugin>

    </model>
</sdf>

